<?xml version="1.0" ?>
<!-- =================================================================================== -->
<!-- |    This document was autogenerated by xacro from roboto2_gazebo.urdf.xacro      | -->
<!-- |    EDITING THIS FILE BY HAND IS NOT RECOMMENDED                                 | -->
<!-- =================================================================================== -->
<!--FIX LIMIT AND THE NOMENCLATURE: JOINTS AND LINK NUMBER IS OFF-->
<!--FIX THE MODEL DIMENSION: FOR LINK BASE AND LINK1-->
<!--ADD INERTIA FOR ALL LINKS-->
<!--REVISE DH PARAMETERS-->
<!-- REDO LINKS 6 and 7 -->
<!--  -->
<!--USE XARCO AND TRANSFER TO SRDF FOR GAZEBO-->
<robot name="roboto_gazebo" xmlns:xacro="http://ros.org/wiki/xacro">
  <material name="orange">
    <color rgba="0.756 0.3608 0.0392 1"/>
  </material>
  <material name="silver">
    <color rgba="0.6157 0.8392 0.9411 1"/>
  </material>
  <link name="world"/>
  <link name="base" xmlns:xacro="http://ros.org/wiki/xacro">
    <visual>
      <geometry>
        <mesh filename="package://urdf_models/meshes/base.STL"/>
      </geometry>
      <origin rpy="0 0 0" xyz="0 0 0"/>
      <material name="orange"/>
    </visual>
    <inertial>
      <origin rpy="0 0 0" xyz="-0.11257 -4.1589E-05 0.057533"/>
      <mass value="25.417"/>
      <inertia ixx="0.347632032016038" ixy="-0.000497937869254212" ixz="0.0371909126715644" iyy="0.710520929572187" iyz="0.000244473496051384" izz="0.978461123632107"/>
    </inertial>
  </link>
  <link name="link1" xmlns:xacro="http://ros.org/wiki/xacro">
    <visual>
      <geometry>
        <mesh filename="package://urdf_models/meshes/link1.STL"/>
      </geometry>
      <origin rpy="0 0 0" xyz="0 0 0"/>
      <material name="orange"/>
    </visual>
    <inertial>
      <origin rpy="0 0 0" xyz="0.048532 0.0047642 0.2152"/>
      <mass value="32.007"/>
      <inertia ixx="1.06695162498236" ixy="0.0263563429413544" ixz="-0.227777437748705" iyy="0.810219541810416" iyz="0.00112484567476821" izz="0.977594438459942"/>
    </inertial>
  </link>
  <joint name="world_to_base" type="fixed">
    <parent link="world"/>
    <child link="base"/>
    <origin xyz="0 0 0"/>
  </joint>
  <joint name="joint1" type="revolute">
    <axis xyz="0 0 1"/>
    <limit effort="50.0" lower="2.96706666667" upper="-2.96706666667" velocity="5"/>
    <origin rpy="0 0 0" xyz="0 0 0.118"/>
    <parent link="base"/>
    <child link="link1"/>
  </joint>
  <link name="link2">
    <visual>
      <geometry>
        <mesh filename="package://urdf_models/meshes/link2.STL"/>
      </geometry>
      <origin rpy="0 0 0" xyz="0 0 0"/>
      <material name="orange"/>
    </visual>
    <inertial>
      <origin rpy="0 0 0" xyz="0.26821 -0.026226 -0.00043323"/>
      <mass value="7.6192"/>
      <inertia ixx="0.0182518895695961" ixy="0.000288617141409028" ixz="-0.000801408670696314" iyy="0.282929525631837" iyz="0.000419364871130956" izz="0.283301435599079"/>
    </inertial>
  </link>
  <joint name="joint2" type="revolute">
    <axis xyz="0 0 1"/>
    <limit effort="50.0" lower="-2.96706666667" upper="1.22173333333" velocity="5.0"/>
    <!--LIMITS AND ORIGIN NEED CORRECTION -->
    <origin rpy="-1.5707 0 0" xyz="0.15 0 0.345"/>
    <parent link="link1"/>
    <child link="link2"/>
  </joint>
  <link name="link3" xmlns:xacro="https//ros.org/wiki/xacro">
    <visual>
      <geometry>
        <mesh filename="package://urdf_models/meshes/link3.STL"/>
      </geometry>
      <origin rpy="0 0 1.5707" xyz="0 0 0"/>
      <material name="orange"/>
    </visual>
    <inertial>
      <origin rpy="0 0 0" xyz="0.032316 -0.10506 -0.027437"/>
      <mass value="7.4487"/>
      <inertia ixx="0.0559221269064628" ixy="0.00737491499245027" ixz="0.00817092524689219" iyy="0.0796970494385453" iyz="-0.00512048798704862" izz="0.0723378108896853"/>
    </inertial>
  </link>
  <joint name="joint3" type="revolute">
    <axis xyz="0 0 1"/>
    <!-- LIMITS AND ORIGIN NEED CORRECTION -->
    <limit effort="5.0" lower="-1.13446666667" upper="1.22173333333" velocity="5.0"/>
    <origin rpy="0 0 0" xyz="0.6 0 0"/>
    <parent link="link2"/>
    <child link="link3"/>
  </joint>
  <link name="link4" xmlns:xacro="http://ros.org/wiki/xacro">
    <visual>
      <geometry>
        <mesh filename="package://urdf_models/meshes/link4_2nd.STL"/>
      </geometry>
      <origin rpy="1.5708 0 0" xyz="0 0 0"/>
      <material name="silver"/>
    </visual>
    <inertial>
      <origin rpy="0 0 0" xyz="-5.9739E-14 -2.8013999999887E-06 0.18449"/>
      <mass value="11.024"/>
      <inertia ixx="1.04704842520385" ixy="0.00134671229464565" ixz="-2.37066307853063E-13" iyy="1.04790395781747" iyz="1.57581187945355E-05" izz="0.0232013100878432"/>
    </inertial>
  </link>
  <joint name="joint4" type="revolute">
    <axis xyz="0 0 1"/>
    <limit effort="50.0" lower="-2.618" upper="2.618" velocity="5.0"/>
    <origin rpy="-1.5707 0 0" xyz="0.12 0 0"/>
    <parent link="link3"/>
    <child link="link4"/>
  </joint>
  <link name="link5" xmlns:xacro="http://ros.org/wiki/xacro">
    <visual>
      <geometry>
        <mesh filename="package://urdf_models/meshes/link5.STL"/>
      </geometry>
      <origin rpy="0 0 -1.5708" xyz="0 0 0"/>
      <material name="orange"/>
    </visual>
    <inertial>
      <origin rpy="0 0 0" xyz="-0.0084108 -5.5325E-17 6.6719E-19"/>
      <mass value="0.29435"/>
      <inertia ixx="0.000179373469228521" ixy="-7.75446618979695E-19" ixz="-9.08300569341961E-21" iyy="0.000297851605472254" iyz="8.40105309624101E-22" izz="0.000418100955158741"/>
    </inertial>
  </link>
  <joint name="joint5" type="revolute">
    <axis xyz="0 0 1"/>
    <limit effort="50.0" lower="-2.00713333333" upper="2.00713333333" velocity="5.0"/>
    <origin rpy="1.5708 0 0" xyz="0 0 0.72"/>
    <parent link="link4"/>
    <child link="link5"/>
  </joint>
  <link name="link6" xmlns:xacro="http://ros.org/wiki/xacro">
    <visual>
      <geometry>
        <mesh filename="package://urdf_models/meshes/link6.STL"/>
      </geometry>
      <origin rpy="0 0 0" xyz="0 0 0"/>
      <material name="silver"/>
    </visual>
    <inertial>
      <origin rpy="0 0 0" xyz="-0.00075 -0.00034342 -0.00018608"/>
      <mass value="0.016853"/>
      <inertia ixx="2.80644119747642E-06" ixy="2.66387834592345E-22" ixz="9.08671417210683E-21" iyy="2.92418288601994E-06" iyz="-3.26381144284828E-09" izz="5.43699994911195E-06"/>
    </inertial>
  </link>
  <!--LINK6 IS A DUMMY LINK TO RECONCILE THE LAST JOINT WITH THE END EFFECTOR-->
  <joint name="joint6" type="revolute">
    <axis xyz="0 0 1"/>
    <limit effort="50.0" lower="-5.236" upper="5.236" velocity="5.0"/>
    <origin rpy="-1.5708 0 0" xyz="0 0 0"/>
    <parent link="link5"/>
    <child link="link6"/>
  </joint>
  <link name="link7">
    <!--visual>
			<geometry>
				<mesh filename="package://urdf_models/meshes/link6.STL"/>
			</geometry>
			<origin xyz="0 0 0" rpy="0 0 0"/>
			<material name="silver"/>
		</visual-->
  </link>
  <joint name="joint7" type="fixed">
    <!--axis xyz="0 0 1"/>
		<limit effort="1.0" lower="0" upper="3.142" velocity="5.0"/-->
    <origin rpy="0 0 0" xyz="0 0 0.085"/>
    <parent link="link6"/>
    <child link="link7"/>
  </joint>
</robot>

